{
 "cells": [
  {
   "cell_type": "code",
   "execution_count": 2,
   "id": "1b7bd723-bc86-4a3e-bee1-d2e76125a204",
   "metadata": {},
   "outputs": [],
   "source": [
    "import tensorflow as tf\n",
    "from tensorflow.keras import layers"
   ]
  },
  {
   "cell_type": "code",
   "execution_count": 3,
   "id": "5577d539-5793-4f1a-9137-6c3c86d05e52",
   "metadata": {},
   "outputs": [],
   "source": [
    "x=[1,2,3,4,5]\n",
    "y=[2,4,6,8,10]"
   ]
  },
  {
   "cell_type": "code",
   "execution_count": 10,
   "id": "422edf8a-86d7-49f1-ad29-6ed55339e878",
   "metadata": {},
   "outputs": [],
   "source": [
    "data_x = tf.convert_to_tensor(x)"
   ]
  },
  {
   "cell_type": "code",
   "execution_count": 12,
   "id": "e8e856b6-0a32-4bc0-92a6-a125024891a7",
   "metadata": {},
   "outputs": [],
   "source": [
    "data_y = tf.convert_to_tensor(x)"
   ]
  },
  {
   "cell_type": "code",
   "execution_count": 11,
   "id": "8f11baf2-bd58-4830-8f93-fd5fd75e1aa2",
   "metadata": {},
   "outputs": [
    {
     "data": {
      "text/plain": [
       "<tf.Tensor: shape=(5,), dtype=int32, numpy=array([1, 2, 3, 4, 5])>"
      ]
     },
     "execution_count": 11,
     "metadata": {},
     "output_type": "execute_result"
    }
   ],
   "source": [
    "data_x"
   ]
  },
  {
   "cell_type": "code",
   "execution_count": 14,
   "id": "dd639cba-0fb4-46dd-a241-c41a9c58bd90",
   "metadata": {},
   "outputs": [
    {
     "name": "stderr",
     "output_type": "stream",
     "text": [
      "C:\\Users\\hp\\AppData\\Local\\Programs\\Python\\Python310\\lib\\site-packages\\keras\\src\\layers\\core\\dense.py:88: UserWarning: Do not pass an `input_shape`/`input_dim` argument to a layer. When using Sequential models, prefer using an `Input(shape)` object as the first layer in the model instead.\n",
      "  super().__init__(activity_regularizer=activity_regularizer, **kwargs)\n"
     ]
    }
   ],
   "source": [
    "model = tf.keras.Sequential([\n",
    "   \n",
    "    layers.Dense(1,input_shape=[1]),\n",
    "    # layers.Dense(10, activation=\"softmax\")\n",
    "])"
   ]
  },
  {
   "cell_type": "code",
   "execution_count": 15,
   "id": "78620eac-f1d5-465a-a9bf-77f26b7f57d8",
   "metadata": {},
   "outputs": [],
   "source": [
    "model.compile(\n",
    "    optimizer=\"adam\",\n",
    "    loss=tf.keras.losses.SparseCategoricalCrossentropy(from_logits=True),\n",
    "    metrics=[\"accuracy\"]\n",
    ")"
   ]
  },
  {
   "cell_type": "code",
   "execution_count": 16,
   "id": "2d1bf651-c0ff-46a3-81ad-8ec4ab33d986",
   "metadata": {},
   "outputs": [
    {
     "name": "stdout",
     "output_type": "stream",
     "text": [
      "Epoch 1/10\n"
     ]
    },
    {
     "ename": "InvalidArgumentError",
     "evalue": "Graph execution error:\n\nDetected at node compile_loss/sparse_categorical_crossentropy/SparseSoftmaxCrossEntropyWithLogits/SparseSoftmaxCrossEntropyWithLogits defined at (most recent call last):\n  File \"C:\\Users\\hp\\AppData\\Local\\Programs\\Python\\Python310\\lib\\runpy.py\", line 196, in _run_module_as_main\n\n  File \"C:\\Users\\hp\\AppData\\Local\\Programs\\Python\\Python310\\lib\\runpy.py\", line 86, in _run_code\n\n  File \"C:\\Users\\hp\\AppData\\Local\\Programs\\Python\\Python310\\lib\\site-packages\\ipykernel_launcher.py\", line 17, in <module>\n\n  File \"C:\\Users\\hp\\AppData\\Local\\Programs\\Python\\Python310\\lib\\site-packages\\traitlets\\config\\application.py\", line 1043, in launch_instance\n\n  File \"C:\\Users\\hp\\AppData\\Local\\Programs\\Python\\Python310\\lib\\site-packages\\ipykernel\\kernelapp.py\", line 736, in start\n\n  File \"C:\\Users\\hp\\AppData\\Local\\Programs\\Python\\Python310\\lib\\site-packages\\tornado\\platform\\asyncio.py\", line 195, in start\n\n  File \"C:\\Users\\hp\\AppData\\Local\\Programs\\Python\\Python310\\lib\\asyncio\\base_events.py\", line 603, in run_forever\n\n  File \"C:\\Users\\hp\\AppData\\Local\\Programs\\Python\\Python310\\lib\\asyncio\\base_events.py\", line 1909, in _run_once\n\n  File \"C:\\Users\\hp\\AppData\\Local\\Programs\\Python\\Python310\\lib\\asyncio\\events.py\", line 80, in _run\n\n  File \"C:\\Users\\hp\\AppData\\Local\\Programs\\Python\\Python310\\lib\\site-packages\\ipykernel\\kernelbase.py\", line 516, in dispatch_queue\n\n  File \"C:\\Users\\hp\\AppData\\Local\\Programs\\Python\\Python310\\lib\\site-packages\\ipykernel\\kernelbase.py\", line 505, in process_one\n\n  File \"C:\\Users\\hp\\AppData\\Local\\Programs\\Python\\Python310\\lib\\site-packages\\ipykernel\\kernelbase.py\", line 412, in dispatch_shell\n\n  File \"C:\\Users\\hp\\AppData\\Local\\Programs\\Python\\Python310\\lib\\site-packages\\ipykernel\\kernelbase.py\", line 740, in execute_request\n\n  File \"C:\\Users\\hp\\AppData\\Local\\Programs\\Python\\Python310\\lib\\site-packages\\ipykernel\\ipkernel.py\", line 422, in do_execute\n\n  File \"C:\\Users\\hp\\AppData\\Local\\Programs\\Python\\Python310\\lib\\site-packages\\ipykernel\\zmqshell.py\", line 546, in run_cell\n\n  File \"C:\\Users\\hp\\AppData\\Local\\Programs\\Python\\Python310\\lib\\site-packages\\IPython\\core\\interactiveshell.py\", line 3009, in run_cell\n\n  File \"C:\\Users\\hp\\AppData\\Local\\Programs\\Python\\Python310\\lib\\site-packages\\IPython\\core\\interactiveshell.py\", line 3064, in _run_cell\n\n  File \"C:\\Users\\hp\\AppData\\Local\\Programs\\Python\\Python310\\lib\\site-packages\\IPython\\core\\async_helpers.py\", line 129, in _pseudo_sync_runner\n\n  File \"C:\\Users\\hp\\AppData\\Local\\Programs\\Python\\Python310\\lib\\site-packages\\IPython\\core\\interactiveshell.py\", line 3269, in run_cell_async\n\n  File \"C:\\Users\\hp\\AppData\\Local\\Programs\\Python\\Python310\\lib\\site-packages\\IPython\\core\\interactiveshell.py\", line 3448, in run_ast_nodes\n\n  File \"C:\\Users\\hp\\AppData\\Local\\Programs\\Python\\Python310\\lib\\site-packages\\IPython\\core\\interactiveshell.py\", line 3508, in run_code\n\n  File \"C:\\Users\\hp\\AppData\\Local\\Temp\\ipykernel_11124\\1349307560.py\", line 1, in <module>\n\n  File \"C:\\Users\\hp\\AppData\\Local\\Programs\\Python\\Python310\\lib\\site-packages\\keras\\src\\utils\\traceback_utils.py\", line 117, in error_handler\n\n  File \"C:\\Users\\hp\\AppData\\Local\\Programs\\Python\\Python310\\lib\\site-packages\\keras\\src\\backend\\tensorflow\\trainer.py\", line 325, in fit\n\n  File \"C:\\Users\\hp\\AppData\\Local\\Programs\\Python\\Python310\\lib\\site-packages\\keras\\src\\backend\\tensorflow\\trainer.py\", line 118, in one_step_on_iterator\n\n  File \"C:\\Users\\hp\\AppData\\Local\\Programs\\Python\\Python310\\lib\\site-packages\\keras\\src\\backend\\tensorflow\\trainer.py\", line 106, in one_step_on_data\n\n  File \"C:\\Users\\hp\\AppData\\Local\\Programs\\Python\\Python310\\lib\\site-packages\\keras\\src\\backend\\tensorflow\\trainer.py\", line 60, in train_step\n\n  File \"C:\\Users\\hp\\AppData\\Local\\Programs\\Python\\Python310\\lib\\site-packages\\keras\\src\\trainers\\trainer.py\", line 322, in compute_loss\n\n  File \"C:\\Users\\hp\\AppData\\Local\\Programs\\Python\\Python310\\lib\\site-packages\\keras\\src\\trainers\\compile_utils.py\", line 605, in __call__\n\n  File \"C:\\Users\\hp\\AppData\\Local\\Programs\\Python\\Python310\\lib\\site-packages\\keras\\src\\trainers\\compile_utils.py\", line 641, in call\n\n  File \"C:\\Users\\hp\\AppData\\Local\\Programs\\Python\\Python310\\lib\\site-packages\\keras\\src\\losses\\loss.py\", line 42, in __call__\n\n  File \"C:\\Users\\hp\\AppData\\Local\\Programs\\Python\\Python310\\lib\\site-packages\\keras\\src\\losses\\losses.py\", line 22, in call\n\n  File \"C:\\Users\\hp\\AppData\\Local\\Programs\\Python\\Python310\\lib\\site-packages\\keras\\src\\losses\\losses.py\", line 1714, in sparse_categorical_crossentropy\n\n  File \"C:\\Users\\hp\\AppData\\Local\\Programs\\Python\\Python310\\lib\\site-packages\\keras\\src\\ops\\nn.py\", line 1554, in sparse_categorical_crossentropy\n\n  File \"C:\\Users\\hp\\AppData\\Local\\Programs\\Python\\Python310\\lib\\site-packages\\keras\\src\\backend\\tensorflow\\nn.py\", line 633, in sparse_categorical_crossentropy\n\nReceived a label value of 5 which is outside the valid range of [0, 1).  Label values: 3 5 4 1 2\n\t [[{{node compile_loss/sparse_categorical_crossentropy/SparseSoftmaxCrossEntropyWithLogits/SparseSoftmaxCrossEntropyWithLogits}}]] [Op:__inference_one_step_on_iterator_756]",
     "output_type": "error",
     "traceback": [
      "\u001b[1;31m---------------------------------------------------------------------------\u001b[0m",
      "\u001b[1;31mInvalidArgumentError\u001b[0m                      Traceback (most recent call last)",
      "Cell \u001b[1;32mIn[16], line 1\u001b[0m\n\u001b[1;32m----> 1\u001b[0m \u001b[43mmodel\u001b[49m\u001b[38;5;241;43m.\u001b[39;49m\u001b[43mfit\u001b[49m\u001b[43m(\u001b[49m\u001b[43mdata_x\u001b[49m\u001b[43m,\u001b[49m\u001b[43m \u001b[49m\u001b[43mdata_y\u001b[49m\u001b[43m,\u001b[49m\u001b[43m \u001b[49m\u001b[43mepochs\u001b[49m\u001b[38;5;241;43m=\u001b[39;49m\u001b[38;5;241;43m10\u001b[39;49m\u001b[43m)\u001b[49m\n",
      "File \u001b[1;32m~\\AppData\\Local\\Programs\\Python\\Python310\\lib\\site-packages\\keras\\src\\utils\\traceback_utils.py:122\u001b[0m, in \u001b[0;36mfilter_traceback.<locals>.error_handler\u001b[1;34m(*args, **kwargs)\u001b[0m\n\u001b[0;32m    119\u001b[0m     filtered_tb \u001b[38;5;241m=\u001b[39m _process_traceback_frames(e\u001b[38;5;241m.\u001b[39m__traceback__)\n\u001b[0;32m    120\u001b[0m     \u001b[38;5;66;03m# To get the full stack trace, call:\u001b[39;00m\n\u001b[0;32m    121\u001b[0m     \u001b[38;5;66;03m# `keras.config.disable_traceback_filtering()`\u001b[39;00m\n\u001b[1;32m--> 122\u001b[0m     \u001b[38;5;28;01mraise\u001b[39;00m e\u001b[38;5;241m.\u001b[39mwith_traceback(filtered_tb) \u001b[38;5;28;01mfrom\u001b[39;00m \u001b[38;5;28;01mNone\u001b[39;00m\n\u001b[0;32m    123\u001b[0m \u001b[38;5;28;01mfinally\u001b[39;00m:\n\u001b[0;32m    124\u001b[0m     \u001b[38;5;28;01mdel\u001b[39;00m filtered_tb\n",
      "File \u001b[1;32m~\\AppData\\Local\\Programs\\Python\\Python310\\lib\\site-packages\\tensorflow\\python\\eager\\execute.py:53\u001b[0m, in \u001b[0;36mquick_execute\u001b[1;34m(op_name, num_outputs, inputs, attrs, ctx, name)\u001b[0m\n\u001b[0;32m     51\u001b[0m \u001b[38;5;28;01mtry\u001b[39;00m:\n\u001b[0;32m     52\u001b[0m   ctx\u001b[38;5;241m.\u001b[39mensure_initialized()\n\u001b[1;32m---> 53\u001b[0m   tensors \u001b[38;5;241m=\u001b[39m pywrap_tfe\u001b[38;5;241m.\u001b[39mTFE_Py_Execute(ctx\u001b[38;5;241m.\u001b[39m_handle, device_name, op_name,\n\u001b[0;32m     54\u001b[0m                                       inputs, attrs, num_outputs)\n\u001b[0;32m     55\u001b[0m \u001b[38;5;28;01mexcept\u001b[39;00m core\u001b[38;5;241m.\u001b[39m_NotOkStatusException \u001b[38;5;28;01mas\u001b[39;00m e:\n\u001b[0;32m     56\u001b[0m   \u001b[38;5;28;01mif\u001b[39;00m name \u001b[38;5;129;01mis\u001b[39;00m \u001b[38;5;129;01mnot\u001b[39;00m \u001b[38;5;28;01mNone\u001b[39;00m:\n",
      "\u001b[1;31mInvalidArgumentError\u001b[0m: Graph execution error:\n\nDetected at node compile_loss/sparse_categorical_crossentropy/SparseSoftmaxCrossEntropyWithLogits/SparseSoftmaxCrossEntropyWithLogits defined at (most recent call last):\n  File \"C:\\Users\\hp\\AppData\\Local\\Programs\\Python\\Python310\\lib\\runpy.py\", line 196, in _run_module_as_main\n\n  File \"C:\\Users\\hp\\AppData\\Local\\Programs\\Python\\Python310\\lib\\runpy.py\", line 86, in _run_code\n\n  File \"C:\\Users\\hp\\AppData\\Local\\Programs\\Python\\Python310\\lib\\site-packages\\ipykernel_launcher.py\", line 17, in <module>\n\n  File \"C:\\Users\\hp\\AppData\\Local\\Programs\\Python\\Python310\\lib\\site-packages\\traitlets\\config\\application.py\", line 1043, in launch_instance\n\n  File \"C:\\Users\\hp\\AppData\\Local\\Programs\\Python\\Python310\\lib\\site-packages\\ipykernel\\kernelapp.py\", line 736, in start\n\n  File \"C:\\Users\\hp\\AppData\\Local\\Programs\\Python\\Python310\\lib\\site-packages\\tornado\\platform\\asyncio.py\", line 195, in start\n\n  File \"C:\\Users\\hp\\AppData\\Local\\Programs\\Python\\Python310\\lib\\asyncio\\base_events.py\", line 603, in run_forever\n\n  File \"C:\\Users\\hp\\AppData\\Local\\Programs\\Python\\Python310\\lib\\asyncio\\base_events.py\", line 1909, in _run_once\n\n  File \"C:\\Users\\hp\\AppData\\Local\\Programs\\Python\\Python310\\lib\\asyncio\\events.py\", line 80, in _run\n\n  File \"C:\\Users\\hp\\AppData\\Local\\Programs\\Python\\Python310\\lib\\site-packages\\ipykernel\\kernelbase.py\", line 516, in dispatch_queue\n\n  File \"C:\\Users\\hp\\AppData\\Local\\Programs\\Python\\Python310\\lib\\site-packages\\ipykernel\\kernelbase.py\", line 505, in process_one\n\n  File \"C:\\Users\\hp\\AppData\\Local\\Programs\\Python\\Python310\\lib\\site-packages\\ipykernel\\kernelbase.py\", line 412, in dispatch_shell\n\n  File \"C:\\Users\\hp\\AppData\\Local\\Programs\\Python\\Python310\\lib\\site-packages\\ipykernel\\kernelbase.py\", line 740, in execute_request\n\n  File \"C:\\Users\\hp\\AppData\\Local\\Programs\\Python\\Python310\\lib\\site-packages\\ipykernel\\ipkernel.py\", line 422, in do_execute\n\n  File \"C:\\Users\\hp\\AppData\\Local\\Programs\\Python\\Python310\\lib\\site-packages\\ipykernel\\zmqshell.py\", line 546, in run_cell\n\n  File \"C:\\Users\\hp\\AppData\\Local\\Programs\\Python\\Python310\\lib\\site-packages\\IPython\\core\\interactiveshell.py\", line 3009, in run_cell\n\n  File \"C:\\Users\\hp\\AppData\\Local\\Programs\\Python\\Python310\\lib\\site-packages\\IPython\\core\\interactiveshell.py\", line 3064, in _run_cell\n\n  File \"C:\\Users\\hp\\AppData\\Local\\Programs\\Python\\Python310\\lib\\site-packages\\IPython\\core\\async_helpers.py\", line 129, in _pseudo_sync_runner\n\n  File \"C:\\Users\\hp\\AppData\\Local\\Programs\\Python\\Python310\\lib\\site-packages\\IPython\\core\\interactiveshell.py\", line 3269, in run_cell_async\n\n  File \"C:\\Users\\hp\\AppData\\Local\\Programs\\Python\\Python310\\lib\\site-packages\\IPython\\core\\interactiveshell.py\", line 3448, in run_ast_nodes\n\n  File \"C:\\Users\\hp\\AppData\\Local\\Programs\\Python\\Python310\\lib\\site-packages\\IPython\\core\\interactiveshell.py\", line 3508, in run_code\n\n  File \"C:\\Users\\hp\\AppData\\Local\\Temp\\ipykernel_11124\\1349307560.py\", line 1, in <module>\n\n  File \"C:\\Users\\hp\\AppData\\Local\\Programs\\Python\\Python310\\lib\\site-packages\\keras\\src\\utils\\traceback_utils.py\", line 117, in error_handler\n\n  File \"C:\\Users\\hp\\AppData\\Local\\Programs\\Python\\Python310\\lib\\site-packages\\keras\\src\\backend\\tensorflow\\trainer.py\", line 325, in fit\n\n  File \"C:\\Users\\hp\\AppData\\Local\\Programs\\Python\\Python310\\lib\\site-packages\\keras\\src\\backend\\tensorflow\\trainer.py\", line 118, in one_step_on_iterator\n\n  File \"C:\\Users\\hp\\AppData\\Local\\Programs\\Python\\Python310\\lib\\site-packages\\keras\\src\\backend\\tensorflow\\trainer.py\", line 106, in one_step_on_data\n\n  File \"C:\\Users\\hp\\AppData\\Local\\Programs\\Python\\Python310\\lib\\site-packages\\keras\\src\\backend\\tensorflow\\trainer.py\", line 60, in train_step\n\n  File \"C:\\Users\\hp\\AppData\\Local\\Programs\\Python\\Python310\\lib\\site-packages\\keras\\src\\trainers\\trainer.py\", line 322, in compute_loss\n\n  File \"C:\\Users\\hp\\AppData\\Local\\Programs\\Python\\Python310\\lib\\site-packages\\keras\\src\\trainers\\compile_utils.py\", line 605, in __call__\n\n  File \"C:\\Users\\hp\\AppData\\Local\\Programs\\Python\\Python310\\lib\\site-packages\\keras\\src\\trainers\\compile_utils.py\", line 641, in call\n\n  File \"C:\\Users\\hp\\AppData\\Local\\Programs\\Python\\Python310\\lib\\site-packages\\keras\\src\\losses\\loss.py\", line 42, in __call__\n\n  File \"C:\\Users\\hp\\AppData\\Local\\Programs\\Python\\Python310\\lib\\site-packages\\keras\\src\\losses\\losses.py\", line 22, in call\n\n  File \"C:\\Users\\hp\\AppData\\Local\\Programs\\Python\\Python310\\lib\\site-packages\\keras\\src\\losses\\losses.py\", line 1714, in sparse_categorical_crossentropy\n\n  File \"C:\\Users\\hp\\AppData\\Local\\Programs\\Python\\Python310\\lib\\site-packages\\keras\\src\\ops\\nn.py\", line 1554, in sparse_categorical_crossentropy\n\n  File \"C:\\Users\\hp\\AppData\\Local\\Programs\\Python\\Python310\\lib\\site-packages\\keras\\src\\backend\\tensorflow\\nn.py\", line 633, in sparse_categorical_crossentropy\n\nReceived a label value of 5 which is outside the valid range of [0, 1).  Label values: 3 5 4 1 2\n\t [[{{node compile_loss/sparse_categorical_crossentropy/SparseSoftmaxCrossEntropyWithLogits/SparseSoftmaxCrossEntropyWithLogits}}]] [Op:__inference_one_step_on_iterator_756]"
     ]
    }
   ],
   "source": [
    "model.fit(data_x, data_y, epochs=10)"
   ]
  },
  {
   "cell_type": "code",
   "execution_count": null,
   "id": "53785020-ebfa-4e66-a13f-3bfbbce74098",
   "metadata": {},
   "outputs": [],
   "source": []
  }
 ],
 "metadata": {
  "kernelspec": {
   "display_name": "Python 3 (ipykernel)",
   "language": "python",
   "name": "python3"
  },
  "language_info": {
   "codemirror_mode": {
    "name": "ipython",
    "version": 3
   },
   "file_extension": ".py",
   "mimetype": "text/x-python",
   "name": "python",
   "nbconvert_exporter": "python",
   "pygments_lexer": "ipython3",
   "version": "3.10.10"
  }
 },
 "nbformat": 4,
 "nbformat_minor": 5
}
